INFO      : 25/07/2019 05:32:06 PM: __init__                       Line: 361 in DQclient.py                         HTTP Client initialised with keyfile: /workspace/PRISE/src/engine/connect/.assimila_dq
WARNING   : 25/07/2019 05:32:07 PM: get                            Line: 392 in DQclient.py                         Error in client get : Exception({'Server': 'BaseHTTP/0.6 Python/3.6.6', 'Date': 'Thu, 25 Jul 2019 16:32:07 GMT', 'Error': '(\'DQ get metadata failed.\', \'Unable to get wkt name from tile name: zam_prise\', \'Traceback (most recent call last):\\n  File "/workspace/PRISE/src/datacube/dq_database/db_view.py", line 819, in get_wkt_from_tilename\\n    return self.db_conn.get(sql_tile)[0][0]\\nIndexError: list index out of range\\n\\nThe above exception was the direct cause of the following exception:\\n\\nTraceback (most recent call last):\\n  File "/workspace/PRISE/src/datacube/dataserver/server.py", line 276, in do_POST\\n    permission=dq_perm)\\n  File "/workspace/PRISE/src/datacube/dq_manager.py", line 297, in get_metadata\\n    return self.db_view.get_metadata(meta_get_list)\\n  File "/workspace/PRISE/src/datacube/dq_database/db_view.py", line 452, in get_metadata\\n    df = self.get_long_metadata(subproduct_id, details)\\n  File "/workspace/PRISE/src/datacube/dq_database/db_view.py", line 624, in get_long_metadata\\n    details[meta_lookup.TILE.value])\\n  File "/workspace/PRISE/src/datacube/dq_database/db_view.py", line 824, in get_wkt_from_tilename\\n    raise DQError(err_msg) from e\\nsrc.datacube.dq_exceptions.DQError: \\\'Unable to get wkt name from tile name: zam_prise\\\'\\n\')'},)
