INFO      : 22/08/2019 04:28:04 PM: __init__                       Line: 395 in DQclient.py                         HTTP Client initialised with keyfile: C:/Users/Jenny/AppData/Roaming/QGIS/QGIS3\profiles\default/python/plugins\assimila_datacube\DQTools\DQTools\connect\.assimila_dq
WARNING   : 22/08/2019 04:28:04 PM: get                            Line: 426 in DQclient.py                         Error in client get : Exception('\'DQ check database failed.\', \'No permission to use bespoke searches. Try general search instead\', \'Traceback most recent call last:\n  File "/workspace/datacube/src/datacube/dataserver/server.py", line 284, in do_POST\n    request[ \'bespoke_search \'], permission=dq_perm\n  File "/workspace/datacube/src/datacube/dq_manager.py", line 110, in search_database_bespoke\n    raise DQError \'No permission to use bespoke searches. Try  \'\nsrc.datacube.dq_exceptions.DQError:  \'No permission to use bespoke searches. Try general search instead \'\n\'')
